Workbook

Sheet Checklist
A1: # | B1: Task | C1: Responsible | D1: When? | E1: Status
A2: 1 | B2: Paid Community Data | C2: Himanshu | D2: Pre launch | E2: Completed
A3: 2 | B3: Static code deployment | C3: Mahir | D3: Pre launch | E3: WIP
A4: 3 | B4: Cron jobs | C4: Mahir | D4: Pre launch | E4: WIP
A5: 4 | B5: International Payments | C5: Mahir | D5: Pre launch | E5: Completed
A6: 5 | B6: Old data from Excel | C6: Himanshu | D6: Pre launch | E6: Completed
A7: 6 | B7: Old data from Airtable | C7: Himanshu | D7: Pre launch | E7: Completed
A8: 7 | B8: Well being data from airtable | C8: Himanshu | D8: Pre launch | E8: Completed
A9: 8 | B9: Remove testing data | C9: Himanshu | D9: Pre launch | E9: Completed
A10: 9 | B10: Data migration script for old data | C10: Mahir | D10: Pre launch | E10: Pending
A11: 10 | B11: Offset handling script for current members + CM + Owner (create subscription models) | C11: Mahir | D11: Launch | E11: Pending
A12: 11 | B12: Exempted user list | C12: Himanshu | D12: Pre launch | E12: WIP
A13: 12 | B13: Active plan List from webflow CMS | C13: Himanshu | D13: Pre launch | E13: Completed
... A24: 23 | B24: Accepting event payments in transaction table | C24: Mahir | D24: Post Launch | E24: Pending
A25: 24 | B25: Dont remove python geek yet | C25: Himanshu | E25: Pending
A26: 25 | B26: Community Migration cases - Unchai + Garv | C26: Himanshu | D26: Post Launch | E26: Pending
A27: 26 | B27: Manage Refunds | C27: Himanshu | D27: Pre launch | E27: Pending
A28: 27 | B28: Email CM about the release plan + free till 30th (Android only) | C28: Himanshu | D28: Pre launch | E28: Pending
A29: 28 | B29: Create excel for sql plan data | C29: Himanshu | D29: Pre launch | E29: Completed
A30: 29 | B30: Email CM about the release plan + free till 7th July (iOS only) | C30: Himanshu | D30: Post Launch | E30: Pending
A31: 30 | B31: Events for subscriptions segment | C31: Mahir | E31: Pending
A32: 31 | B32: is removbed case for cron job | C32: Himanshu | D32: Pre launch | E32: Completed

Sheet User data - excel
A1: payment_id | B1: plan_id | C1: Community Name | D1: Community_id | E1: plan_name | F1: plan_duration | G1: plan_cost | H1: renew | I1: amount | J1: email | K1: contact | L1: currency | M1: is_international | N1: method | O1: status | P1: created_at | Q1: Users | R1: payment_page_url
A2: pay_GMMPqMJQVOgxYx | C2: Defence tribe | D2: 49831 | F2: Quarterly Plan Plan | G2: 299 | I2: 299 | J2: vedanshved25dec@gmail.com | K2: 917270913144 | L2: INR | M2: FALSE | N2: upi | O2: captured | P2: 44203.607 | Q2: 3372
A3: pay_GMMajKdG9UC7y0 | C3: Defence tribe | D3: 49831 | F3: Quarterly Plan Plan | G3: 299 | I3: 299 | J3: deepakkumar3624@gmail.com | K3: 919717802505 | L3: INR | M3: FALSE | N3: upi | O3: captured | P3: 44203.614 | Q3: 2827
A4: pay_GMRtiGOOiByLTp | C4: Defence tribe | D4: 49831 | F4: Quarterly Plan Plan | G4: 299 | I4: 299 | J4: dalalnishant2@gmail.com | K4: 918168803701 | L4: INR | M4: FALSE | N4: card | O4: captured | P4: 44203.83 | Q4: 3186
A5: pay_GNCHuNu1kJ0zaa | C5: Deutsch In Tandem | D5: 49834 | F5: Half Yearly Plan | G5: 499 | I5: 499 | J5: yogitash22@gmail.com | K5: 918800718020 | L5: INR | M5: FALSE | N5: upi | O5: captured | P5: 44205.721 | Q5: 3250
A6: pay_GNd6dnCUooNQKs | C6: Defence tribe | D6: 49831 | F6: Quarterly Plan Plan | G6: 299 | I6: 299 | J6: hdsinghima@gmail.com | K6: 916005739437 | L6: INR | M6: FALSE | N6: card | O6: captured | P6: 44206.814 | Q6: 1966
A7: pay_GOQEpIS7XcKoir | C7: Defence tribe | D7: 49831 | F7: Quarterly Plan Plan | G7: 299 | I7: 299 | J7: lkmdbani@gmail.com | K7: 918427297182 | L7: INR | M7: FALSE | N7: card | O7: captured | P7: 44208.817 | Q7: NF V2
A8: pay_GPTXtXi4wSTtNa | C8: Deutsch In Tandem | D8: 49834 | F8: Quarterly Plan | G8: 299 | I8: 299 | J8: khanolkardivya@gmail.com | K8: 916263018296 | L8: INR | M8: FALSE | N8: upi | O8: captured | P8: 44211.478 | Q8: 3762
A9: pay_GPy0NlVHv4QR0L | C9: Defence tribe | D9: 49831 | F9: Quarterly Plan Plan | G9: 299 | I9: 299 | J9: padmeshsavaratkar3256@gmail.com | K9: 917218040940 | L9: INR | M9: FALSE | N9: upi | O9: captured | P9: 44212.72 | Q9: 3781
A10: pay_GR4mKgIV1C5RN5 | C10: Defence tribe | D10: 49831 | F10: Quarterly Plan Plan | G10: 299 | I10: 299 | J10: prathampatel7700@gmail.com | K10: 919009992720 | L10: INR | M10: FALSE | N10: upi | O10: captured | P10: 44215.523 | Q10: 4197
A11: pay_GRqz0J18NyaIQD | C11: Defence tribe | D11: 49831 | F11: Quarterly Plan Plan | G11: 299 | I11: 299 | J11: ashishbisht336@gmail.com | K11: 918171705580 | L11: INR | M11: FALSE | N11: upi | O11: captured | P11: 44217.488 | Q11: 4697
A12: pay_GRvBKZGHwgPRjm | C12: Defence tribe | D12: 49831 | F12: Quarterly Plan Plan | G12: 299 | I12: 299 | J12: mauryanitesh484@gmail.com | K12: 917268085630 | L12: INR | M12: FALSE | N12: upi | O12: captured | P12: 44217.659 | Q12: 4786
A13: pay_GSPU6pt7WJaZ5w | C13: Defence tribe | D13: 49831 | F13: Quarterly Plan Plan | G13: 299 | I13: 299 | J13: aniket.kulkarni2912@gmail.com | K13: 917383086100 | L13: INR | M13: FALSE | N13: netbanking | O13: captured | P13: 44218.894 | Q13: 5187
A14: pay_GTAIl8R5CKBaBV | C14: Defence tribe | D14: 49831 | F14: Quarterly Plan Plan | G14: 299 | I14: 299 | J14: maheshdond1998@gmail.com | K14: 918668235424 | L14: INR | M14: FALSE | N14: upi | O14: captured | P14: 44220.802 | Q14: 5857
A15: pay_GUNy0tcPxVDLj1 | C15: Deutsch In Tandem | D15: 49834 | F15: Quarterly Plan | G15: 299 | I15: 299 | J15: akharbanda1@hotmail.com | K15: 918468909258 | L15: INR | M15: FALSE | N15: upi | O15: captured | P15: 44223.887 | Q15: 1954
A16: pay_GUZbjXvudoeP9s | C16: Defence tribe | D16: 49831 | F16: Quarterly Plan Plan | G16: 299 | I16: 299 | J16: sahilshaikh19702@gmail.com | K16: 919370569303 | L16: INR | M16: FALSE | N16: card | O16: captured | P16: 44224.361 | Q16: 6724
A17: pay_GV4jzgzMpB8TC4 | C17: Defence tribe | D17: 49831 | F17: Quarterly Plan Plan | G17: 299 | I17: 299 | J17: 56modinaren56@gmail.com | K17: 916396846910 | L17: INR | M17: FALSE | N17: netbanking | O17: captured | P17: 44225.63 | Q17: 7923
A18: pay_GVODTfpfo5aMnJ | C18: Deutsch In Tandem | D18: 49834 | F18: Quarterly Plan | G18: 299 | I18: 299 | J18: riyay4892@gmail.com | K18: 919959986457 | L18: INR | M18: FALSE | N18: upi | O18: captured | P18: 44226.424 | Q18: 6280
A19: pay_GVRCPtovigqIVp | C19: Deutsch In Tandem | D19: 49834 | F19: Quarterly Plan | G19: 299 | I19: 299 | J19: ku.rkrishna86@gmail.com | K19: 919074974588 | L19: INR | M19: FALSE | N19: upi | O19: captured | P19: 44226.545 | Q19: NF V2
A20: pay_GVVFZ0WR0ZCrEw | C20: Deutsch In Tandem | D20: 49834 | F20: Quarterly Plan | G20: 299 | I20: 299 | J20: sakshisharad01@gmail.com | K20: 917070989596 | L20: INR | M20: FALSE | N20: card | O20: captured | P20: 44226.71 | Q20: 9318
A21: pay_GVxsYaKlbtgSSk | C21: Defence tribe | D21: 49831 | F21: Quarterly Plan Plan | G21: 299 | I21: 299 | J21: msrathore245@gmail.com | K21: 918619552616 | L21: INR | M21: FALSE | N21: upi | O21: captured | P21: 44227.877 | Q21: 9249
A22: pay_GW6xiEDpehVAgv | C22: Deutsch In Tandem | D22: 49834 | F22: Half Yearly Plan | G22: 499 | I22: 499 | J22: vjagadeeshsurya9@gmail.com | K22: 918801416002 | L22: INR | M22: FALSE | N22: upi | O22: captured | P22: 44228.248 | Q22: 2204
A23: pay_GZ8ESWCuUQreEd | C23: Deutsch In Tandem | D23: 49834 | F23: Half Yearly Plan | G23: 499 | I23: 499 | J23: sushamavarghese2002@gmail.com | K23: 917592993781 | L23: INR | M23: FALSE | N23: upi | O23: captured | P23: 44235.881 | Q23: 11776
A24: pay_GZNVgRMMeT8onU | C24: Defence tribe | D24: 49831 | F24: Quarterly Plan Plan | G24: 299 | I24: 299 | J24: abhishektiwarippndc@gmail.com | K24: 919140600963 | L24: INR | M24: FALSE | N24: upi | O24: captured | P24: 44236.503 | Q24: 11830
A25: pay_GaGH4uY9r0ki7N | C25: Defence tribe | D25: 49831 | F25: Quarterly Plan Plan | G25: 299 | I25: 299 | J25: deepanshujhariya2@gmail.com | K25: 917879337462 | L25: INR | M25: FALSE | N25: upi | O25: captured | P25: 44238.735 | Q25: 12725
A26: pay_GaGL6h52VdxV33 | C26: Defence tribe | D26: 49831 | F26: Quarterly Plan Plan | G26: 299 | I26: 299 | J26: akashprajapati959819@gmail.com | K26: 918303205070 | L26: INR | M26: FALSE | N26: upi | O26: captured | P26: 44238.738 | Q26: 12741
A27: pay_GaJdX5gcvc0hza | C27: Deutsch In Tandem | D27: 49834 | F27: Quarterly Plan | G27: 299 | I27: 299 | J27: rheaa131@gmail.com | K27: 917990724041 | L27: INR | M27: FALSE | N27: upi | O27: captured | P27: 44238.873 | Q27: 4827
A28: pay_GaZLrT73PaUIbc | C28: Defence tribe | D28: 49831 | F28: Quarterly Plan Plan | G28: 299 | I28: 299 | J28: sksharma26121999@gmail.com | K28: 918273506739 | L28: INR | M28: FALSE | N28: upi | O28: captured | P28: 44239.513 | Q28: 12920
A29: pay_GaaJY8e9MsBTbQ | C29: Deutsch In Tandem | D29: 49834 | F29: Half Yearly Plan | G29: 499 | I29: 499 | J29: shivanibkdas@gmail.com | K29: 971505493883 | L29: INR | M29: FALSE | N29: card | O29: captured | P29: 44239.552 | Q29: 2133
A30: pay_GbucskLB1arRI6 | C30: Defence tribe | D30: 49831 | F30: Quarterly Plan Plan | G30: 299 | I30: 299 | J30: singhshashank199947@gmail.com | K30: 919354096048 | L30: INR | M30: FALSE | N30: upi | O30: captured | P30: 44242.907 | Q30: 14022
A31: pay_Gc8SndGFUF1kwZ | C31: Defence tribe | D31: 49831 | F31: Quarterly Plan Plan | G31: 299 | I31: 299 | J31: sonitsharma44@gmail.com | K31: 918868001977 | L31: INR | M31: FALSE | N31: upi | O31: captured | P31: 44243.471 | Q31: 14012
... A44: pay_Gho6SlmcgJ8pBD | C44: Defence tribe | D44: 49831 | F44: Quarterly Plan | G44: 499 | I44: 499 | J44: shvineet123@gmail.com | K44: 919310446765 | L44: INR | M44: FALSE | N44: upi | O44: captured | P44: 44257.804 | Q44: 15580
A45: pay_GiEluXNGNJIuZy | C45: Defence tribe | D45: 49831 | F45: Quarterly Plan | G45: 499 | I45: 499 | J45: girja.textiles@gmail.com | K45: 919322695468 | L45: INR | M45: FALSE | N45: card | O45: captured | P45: 44258.891 | Q45: NF V2
A46: pay_GiKGQvIEjyo6f4 | C46: Deutsch In Tandem | D46: 49834 | F46: Quarterly Plan | G46: 299 | I46: 299 | J46: mdatifalam4@gmail.com | K46: 917903350694 | L46: INR | M46: FALSE | N46: upi | O46: captured | P46: 44259.115 | Q46: 11297
A47: pay_GiZESjfLV3JEGB | C47: Deutsch In Tandem | D47: 49834 | F47: Quarterly Plan | G47: 299 | I47: 299 | J47: chirag34upqdhyay@gmail.com | K47: 917226918962 | L47: INR | M47: FALSE | N47: card | O47: captured | P47: 44259.725 | Q47: 16068
A48: pay_GiZR0CKP2WwoBa | C48: Defence Tribe | D48: 49831 | F48: Half Yearly Plan | G48: 799 | I48: 799 | J48: itzcuteansari@gmail.com | K48: 918318980567 | L48: INR | M48: FALSE | N48: upi | O48: captured | P48: 44259.733 | Q48: 16807
A49: pay_Gj3xrba3DwfjRb | C49: Deutsch In Tandem | D49: 49834 | F49: Quarterly Plan | G49: 299 | I49: 299 | J49: gr.venkateshyadav@gmail.com | K49: 919900049665 | L49: INR | M49: FALSE | N49: upi | O49: captured | P49: 44260.977 | Q49: 15838
A50: pay_Gk6gPvgP3OjcV3 | C50: Defence Tribe | D50: 49831 | F50: Half Yearly Plan | G50: 799 | I50: 799 | J50: morenilesh732@gmail.com | K50: 918766847954 | L50: INR | M50: FALSE | N50: upi | O50: captured | P50: 44263.615 | Q50: 15945
A51: pay_GyglY0KRtoIQ2s | C51: De battlers | D51: 49991 | F51: Monthly Plan | G51: 99 | I51: 99 | J51: araithatha3@gmail.com | K51: 919426320716 | L51: INR | M51: FALSE | N51: card | O51: captured | P51: 44300.465 | Q51: 16851
A52: pay_Gz8R6cdZRM5Uh1 | C52: De battlers | D52: 49991 | F52: Monthly Plan | G52: 99 | I52: 99 | J52: raniponmathip@yahoo.com | K52: 919710303309 | L52: INR | M52: FALSE | N52: upi | O52: captured | P52: 44301.593 | Q52: 16881
...

Sheet User data - airtable
A1: payment_id | B1: plan_id | C1: Community Name | D1: Community_id | E1: plan_name | F1: plan_duration | G1: plan_cost | H1: renew | I1: amount | J1: email | K1: phone | L1: =CONCAT(J1,K1) -> emailphone | M1: currency | N1: is_international | O1: method | P1: status | Q1: created_at | R1: user_id | S1: payment_page_url | T1: payment_type
A2: =VLOOKUP(L2,payment_ids!C:D,2,FALSE) -> pay_HLNuFmG6aNQ5Zz | C2: A Blue Lotus Life | D2: 50143 | F2: 6 | G2: 999 | I2: 999 | J2: thehappypankaj@yahoo.com | K2: =+918283088675 -> 918283088675 | L2: =CONCAT(J2,K2) -> thehappypankaj@yahoo.com918283088675 | M2: INR | N2: FALSE | O2: =VLOOKUP(A2,payment_ids!D:E,2,FALSE) -> upi | P2: captured | Q2: 44475.819 | S2: https://hi.likeminds.community/d/a-blue-lotus-life | T2: Subscription
A3: =VLOOKUP(L3,payment_ids!C:D,2,FALSE) -> pay_HNDFyxw24p8Ojm | C3: A Blue Lotus Life | D3: 50143 | F3: 1 | G3: 199 | I3: 199 | J3: pakhi.garg95@gmail.com | K3: =+919808881888 -> 919808881888 | L3: =CONCAT(J3,K3) -> pakhi.garg95@gmail.com919808881888 | M3: INR | N3: FALSE | O3: =VLOOKUP(A3,payment_ids!D:E,2,FALSE) -> upi | P3: captured | Q3: 6/15/2021 10:33 AM | S3: https://hi.likeminds.community/d/a-blue-lotus-life | T3: Subscription
A4: =VLOOKUP(L4,payment_ids!C:D,2,FALSE) -> pay_HNTFkn45M6JhsN | C4: A Blue Lotus Life | D4: 50143 | F4: 1 | G4: 199 | I4: 199 | J4: bhawna.sandeep1130@gmail.com | K4: =+918950904883 -> 918950904883 | L4: =CONCAT(J4,K4) -> bhawna.sandeep1130@gmail.com918950904883 | M4: INR | N4: FALSE | O4: =VLOOKUP(A4,payment_ids!D:E,2,FALSE) -> upi | P4: captured | Q4: 6/16/2021 2:12 AM | S4: https://hi.likeminds.community/d/a-blue-lotus-life | T4: Subscription
A5: =VLOOKUP(L5,payment_ids!C:D,2,FALSE) -> pay_HNjqcFTYoWX0yu | C5: A Blue Lotus Life | D5: 50143 | F5: 6 | G5: 999 | I5: 999 | J5: saumyajoshi89@gmail.com | K5: =+918469114428 -> 918469114428 | L5: =CONCAT(J5,K5) -> saumyajoshi89@gmail.com918469114428 | M5: INR | N5: FALSE | O5: =VLOOKUP(A5,payment_ids!D:E,2,FALSE) -> card | P5: captured | Q5: 6/16/2021 6:44 PM | S5: https://hi.likeminds.community/d/a-blue-lotus-life | T5: Subscription
A6: =VLOOKUP(L6,payment_ids!C:D,2,FALSE) -> pay_HMRMlrYlyFK0Rf | C6: A Blue Lotus Life | D6: 50143 | F6: 1 | G6: 199 | I6: 199 | J6: krishnaraj.bhatns@gmail.com | K6: =+919731761212 -> 919731761212 | L6: =CONCAT(J6,K6) -> krishnaraj.bhatns@gmail.com919731761212 | M6: INR | N6: FALSE | O6: =VLOOKUP(A6,payment_ids!D:E,2,FALSE) -> upi | P6: captured | Q6: 6/20/2021 12:11 PM | S6: https://hi.likeminds.community/d/a-blue-lotus-life#Pricing | T6: Subscription
A7: =VLOOKUP(L7,payment_ids!C:D,2,FALSE) -> pay_HMRMlrYlyFK0Rf | C7: A Blue Lotus Life | D7: 50143 | F7: 1 | G7: 199 | I7: 199 | J7: krishnaraj.bhatns@gmail.com | K7: =+919731761212 -> 919731761212 | L7: =CONCAT(J7,K7) -> krishnaraj.bhatns@gmail.com919731761212 | M7: INR | N7: FALSE | O7: =VLOOKUP(A7,payment_ids!D:E,2,FALSE) -> upi | P7: captured | Q7: 6/20/2021 12:28 PM | S7: https://hi.likeminds.community/d/a-blue-lotus-life#Pricing | T7: Subscription
A8: =VLOOKUP(L8,payment_ids!C:D,2,FALSE) -> pay_H6IvfhXVSJtsVU | C8: Ahoj: Let's Blog | D8: 49997 | F8: 1 | G8: 99 | I8: 99 | J8: tara.lanba1999@gmail.com | K8: =+919582439852 -> 919582439852 | L8: =CONCAT(J8,K8) -> tara.lanba1999@gmail.com919582439852 | M8: INR | N8: FALSE | O8: =VLOOKUP(A8,payment_ids!D:E,2,FALSE) -> upi | P8: captured | Q8: 44260.71 | S8: https://community.likeminds.community/ahoj-lets-blog
A9: =VLOOKUP(L9,payment_ids!C:D,2,FALSE) -> pay_H6M18PniZZxhuH | C9: Ahoj: Let's Blog | D9: 49997 | F9: 1 | G9: 99 | I9: 99 | J9: mahirgupta98@gmail.com | K9: =+919416173796 -> 919416173796 | L9: =CONCAT(J9,K9) -> mahirgupta98@gmail.com919416173796 | M9: INR | N9: FALSE | O9: =VLOOKUP(A9,payment_ids!D:E,2,FALSE) -> upi | P9: captured | Q9: 44260.836 | S9: https://community.likeminds.community/ahoj-lets-blog
A10: =VLOOKUP(L10,payment_ids!C:D,2,FALSE) -> pay_H6OZHMGGwhtkMg | C10: Ahoj: Let's Blog | D10: 49997 | F10: 6 | G10: 349 | I10: 349 | J10: tanvimhatre001@gmail.com | K10: =+919969893269 -> 919969893269 | L10: =CONCAT(J10,K10) -> tanvimhatre001@gmail.com919969893269 | M10: INR | N10: FALSE | O10: =VLOOKUP(A10,payment_ids!D:E,2,FALSE) -> card | P10: captured | Q10: 44260.94 | S10: https://community.likeminds.community/ahoj-lets-blog
A11: =VLOOKUP(L11,payment_ids!C:D,2,FALSE) -> pay_H6ejsTenhxPtgT | C11: Ahoj: Let's Blog | D11: 49997 | F11: 6 | G11: 349 | I11: 349 | J11: nawatheygaurav@gmail.com | K11: =+919819252511 -> 919819252511 | L11: =CONCAT(J11,K11) -> nawatheygaurav@gmail.com919819252511 | M11: INR | N11: FALSE | O11: =VLOOKUP(A11,payment_ids!D:E,2,FALSE) -> upi | P11: captured | Q11: 44291.6 | S11: https://community.likeminds.community/ahoj-lets-blog
A12: =VLOOKUP(L12,payment_ids!C:D,2,FALSE) -> pay_H6gODrRvIOBR2G | C12: Ahoj: Let's Blog | D12: 49997 | F12: 1 | G12: 99 | I12: 99 | J12: leshanimehra1998@gmail.com | K12: =+918600964699 -> 918600964699 | L12: =CONCAT(J12,K12) -> leshanimehra1998@gmail.com918600964699 | M12: INR | N12: FALSE | O12: =VLOOKUP(A12,payment_ids!D:E,2,FALSE) -> upi | P12: captured | Q12: 44291.667 | S12: https://community.likeminds.community/ahoj-lets-blog
A13: =VLOOKUP(L13,payment_ids!C:D,2,FALSE) -> pay_H6gmIveChQnJtL | C13: Ahoj: Let's Blog | D13: 49997 | F13: 1 | G13: 99 | I13: 99 | J13: dezikakol@gmail.com | K13: =+919561542950 -> 919561542950 | L13: =CONCAT(J13,K13) -> dezikakol@gmail.com919561542950 | M13: INR | N13: FALSE | O13: =VLOOKUP(A13,payment_ids!D:E,2,FALSE) -> netbanking | P13: captured | Q13: 44291.683 | S13: https://community.likeminds.community/ahoj-lets-blog
A14: =VLOOKUP(L14,payment_ids!C:D,2,FALSE) -> pay_H6hFPdEWIAM1A2 | C14: Ahoj: Let's Blog | D14: 49997 | F14: 1 | G14: 99 | I14: 99 | J14: iamagsusfreak@gmail.com | K14: =+918129282453 -> 918129282453 | L14: =CONCAT(J14,K14) -> iamagsusfreak@gmail.com918129282453 | M14: INR | N14: FALSE | O14: =VLOOKUP(A14,payment_ids!D:E,2,FALSE) -> upi | P14: captured | Q14: 44291.702 | S14: https://community.likeminds.community/ahoj-lets-blog
A15: =VLOOKUP(L15,payment_ids!C:D,2,FALSE) -> pay_H6cZodbxWfXymQ | C15: Ahoj: Let's Blog | D15: 49997 | F15: 1 | G15: 99 | I15: 99 | J15: abhijit.jha33@gmail.com | K15: =+919711341773 -> 919711341773 | L15: =CONCAT(J15,K15) -> abhijit.jha33@gmail.com919711341773 | M15: INR | N15: FALSE | O15: =VLOOKUP(A15,payment_ids!D:E,2,FALSE) -> upi | P15: captured | Q15: 44291.511 | S15: https://community.likeminds.community/ahoj-lets-blog
A16: =VLOOKUP(L16,payment_ids!C:D,2,FALSE) -> pay_H6qjW9ICOOLM7A | C16: Ahoj: Let's Blog | D16: 49997 | F16: 1 | G16: 99 | I16: 99 | J16: crupam714@gmail.com | K16: =+919330771104 -> 919330771104 | L16: =CONCAT(J16,K16) -> crupam714@gmail.com919330771104 | M16: INR | N16: FALSE | O16: =VLOOKUP(A16,payment_ids!D:E,2,FALSE) -> upi | P16: captured | Q16: 44321.088 | S16: https://community.likeminds.community/ahoj-lets-blog
A17: =VLOOKUP(L17,payment_ids!C:D,2,FALSE) -> pay_H6xvuIL5Vvmaww | C17: Ahoj: Let's Blog | D17: 49997 | F17: 1 | G17: 99 | I17: 99 | J17: benadikam@gmail.com | K17: =+919860729292 -> 919860729292 | L17: =CONCAT(J17,K17) -> benadikam@gmail.com919860729292 | M17: INR | N17: FALSE | O17: =VLOOKUP(A17,payment_ids!D:E,2,FALSE) -> upi | P17: captured | Q17: 44321.382 | S17: https://community.likeminds.community/ahoj-lets-blog
A18: =VLOOKUP(L18,payment_ids!C:D,2,FALSE) -> pay_H70f2pvlDc6itm | C18: Ahoj: Let's Blog | D18: 49997 | F18: 6 | G18: 349 | I18: 349 | J18: travelwithfreddie@gmail.com | K18: =+919998728170 -> 919998728170 | L18: =CONCAT(J18,K18) -> travelwithfreddie@gmail.com919998728170 | M18: INR | N18: FALSE | O18: =VLOOKUP(A18,payment_ids!D:E,2,FALSE) -> upi | P18: captured | Q18: 44321.493 | S18: https://community.likeminds.community/ahoj-lets-blog
A19: =VLOOKUP(L19,payment_ids!C:D,2,FALSE) -> pay_H7Ye3cHPJezSiS | C19: Ahoj: Let's Blog | D19: 49997 | F19: 1 | G19: 99 | I19: 99 | J19: pallspallavi56789@gmail.com | K19: =+917838604128 -> 917838604128 | L19: =CONCAT(J19,K19) -> pallspallavi56789@gmail.com917838604128 | M19: INR | N19: FALSE | O19: =VLOOKUP(A19,payment_ids!D:E,2,FALSE) -> upi | P19: captured | Q19: 44352.878 | S19: https://community.likeminds.community/ahoj-lets-blog
A20: =VLOOKUP(L20,payment_ids!C:D,2,FALSE) -> pay_H7ZH7dwQA7xAMu | C20: Ahoj: Let's Blog | D20: 49997 | F20: 1 | G20: 99 | I20: 99 | J20: debajyoti_wr@hotmail.com | K20: =+919804294752 -> 919804294752 | L20: =CONCAT(J20,K20) -> debajyoti_wr@hotmail.com919804294752 | M20: INR | N20: FALSE | O20: =VLOOKUP(A20,payment_ids!D:E,2,FALSE) -> upi | P20: captured | Q20: 44352.903 | S20: https://community.likeminds.community/ahoj-lets-blog
A21: =VLOOKUP(L21,payment_ids!C:D,2,FALSE) -> pay_H7Nbm5Dv9pLMtM | C21: Ahoj: Let's Blog | D21: 49997 | F21: 1 | G21: 99 | I21: 99 | J21: contact.nandini01@gmail.com | K21: =+917980675481 -> 917980675481 | L21: =CONCAT(J21,K21) -> contact.nandini01@gmail.com917980675481 | M21: INR | N21: FALSE | O21: =VLOOKUP(A21,payment_ids!D:E,2,FALSE) -> upi | P21: captured | Q21: 44352.429 | S21: https://community.likeminds.community/ahoj-lets-blog
A22: =VLOOKUP(L22,payment_ids!C:D,2,FALSE) -> pay_H7akglvqfqvM7T | C22: Ahoj: Let's Blog | D22: 49997 | F22: 3 | G22: 199 | I22: 199 | J22: kartikbalwan@gmail.com | K22: =+919261615151 -> 919261615151 | L22: =CONCAT(J22,K22) -> kartikbalwan@gmail.com919261615151 | M22: INR | N22: FALSE | O22: =VLOOKUP(A22,payment_ids!D:E,2,FALSE) -> upi | P22: captured | Q22: 44352.964 | S22: https://community.likeminds.community/ahoj-lets-blog
A23: =VLOOKUP(L23,payment_ids!C:D,2,FALSE) -> pay_H7pricVWbFOcsz | C23: Ahoj: Let's Blog | D23: 49997 | F23: 1 | G23: 99 | I23: 99 | J23: ajaypanampet@gmail.com | K23: =+918547452646 -> 918547452646 | L23: =CONCAT(J23,K23) -> ajaypanampet@gmail.com918547452646 | M23: INR | N23: FALSE | O23: =VLOOKUP(A23,payment_ids!D:E,2,FALSE) -> upi | P23: captured | Q23: 44382.58 | S23: https://community.likeminds.community/ahoj-lets-blog
A24: =VLOOKUP(L24,payment_ids!C:D,2,FALSE) -> pay_H7rIuIYitrB1K9 | C24: Ahoj: Let's Blog | D24: 49997 | F24: 1 | G24: 99 | I24: 99 | J24: ritusmita01@gmail.com | K24: =+919071865890 -> 919071865890 | L24: =CONCAT(J24,K24) -> ritusmita01@gmail.com919071865890 | M24: INR | N24: FALSE | O24: =VLOOKUP(A24,payment_ids!D:E,2,FALSE) -> upi | P24: captured | Q24: 44382.642 | S24: https://community.likeminds.community/ahoj-lets-blog
A25: =VLOOKUP(L25,payment_ids!C:D,2,FALSE) -> pay_H7l84g4WgUv7ea | C25: Ahoj: Let's Blog | D25: 49997 | F25: 6 | G25: 349 | I25: 349 | J25: raimap994@gmail.com | K25: =+916290860709 -> 916290860709 | L25: =CONCAT(J25,K25) -> raimap994@gmail.com916290860709 | M25: INR | N25: FALSE | O25: =VLOOKUP(A25,payment_ids!D:E,2,FALSE) -> upi | P25: captured | Q25: 44382.388 | S25: https://community.likeminds.community/ahoj-lets-blog
A26: =VLOOKUP(L26,payment_ids!C:D,2,FALSE) -> pay_H8X46YbTfVcxHd | C26: Ahoj: Let's Blog | D26: 49997 | F26: 3 | G26: 199 | I26: 199 | J26: devrahulsingh2104@gmail.com | K26: =+919012341187 -> 919012341187 | L26: =CONCAT(J26,K26) -> devrahulsingh2104@gmail.com919012341187 | M26: INR | N26: FALSE | O26: =VLOOKUP(A26,payment_ids!D:E,2,FALSE) -> upi | P26: captured | Q26: 44444.341 | S26: https://community.likeminds.community/ahoj-lets-blog
A27: =VLOOKUP(L27,payment_ids!C:D,2,FALSE) -> pay_H8lQ5UTVui9dTO | C27: Ahoj: Let's Blog | D27: 49997 | F27: 3 | G27: 199 | I27: 199 | J27: sachin225sandy@gmail.com | K27: =+919030736603 -> 919030736603 | L27: =CONCAT(J27,K27) -> sachin225sandy@gmail.com919030736603 | M27: INR | N27: FALSE | O27: =VLOOKUP(A27,payment_ids!D:E,2,FALSE) -> card | P27: captured | Q27: 44444.926 | S27: https://community.likeminds.community/ahoj-lets-blog
A28: =VLOOKUP(L28,payment_ids!C:D,2,FALSE) -> pay_H8aIV3aCzWiI7l | C28: Ahoj: Let's Blog | D28: 49997 | F28: 3 | G28: 199 | I28: 199 | J28: anuradhashukla143@gmail.com | K28: =+918601624514 -> 918601624514 | L28: =CONCAT(J28,K28) -> anuradhashukla143@gmail.com918601624514 | M28: INR | N28: FALSE | O28: =VLOOKUP(A28,payment_ids!D:E,2,FALSE) -> upi | P28: captured | Q28: 44444.473 | S28: https://community.likeminds.community/ahoj-lets-blog
A29: =VLOOKUP(L29,payment_ids!C:D,2,FALSE) -> pay_H95jxoDSI7LEUB | C29: Ahoj: Let's Blog | D29: 49997 | F29: 3 | G29: 199 | I29: 199 | J29: sandhya.rajan03@gmail.com | K29: =+916380865060 -> 916380865060 | L29: =CONCAT(J29,K29) -> sandhya.rajan03@gmail.com916380865060 | M29: INR | N29: FALSE | O29: =VLOOKUP(A29,payment_ids!D:E,2,FALSE) -> upi | P29: captured | Q29: 44474.754 | S29: https://community.likeminds.community/ahoj-lets-blog
A30: =VLOOKUP(L30,payment_ids!C:D,2,FALSE) -> pay_H97U2lo9toAHVq | C30: Ahoj: Let's Blog | D30: 49997 | F30: 3 | G30: 199 | I30: 199 | J30: opgodara93@gmail.com | K30: =+919587884155 -> 919587884155 | L30: =CONCAT(J30,K30) -> opgodara93@gmail.com919587884155 | M30: INR | N30: FALSE | O30: =VLOOKUP(A30,payment_ids!D:E,2,FALSE) -> upi | P30: captured | Q30: 44474.825 | S30: https://community.likeminds.community/ahoj-lets-blog
A31: =VLOOKUP(L31,payment_ids!C:D,2,FALSE) -> pay_HBWG2W5fG6koig | C31: Ahoj: Let's Blog | D31: 49997 | F31: 3 | G31: 199 | I31: 199 | J31: guru_3@yahoo.com | K31: =+919916242098 -> 919916242098 | L31: =CONCAT(J31,K31) -> guru_3@yahoo.com919916242098 | M31: INR | N31: FALSE | O31: =VLOOKUP(A31,payment_ids!D:E,2,FALSE) -> upi | P31: captured | Q31: 5/16/2021 9:20 PM | S31: https://community.likeminds.community/ahoj-lets-blog
A32: =VLOOKUP(L32,payment_ids!C:D,2,FALSE) -> pay_HBifDwU9dgPVQZ | C32: Ahoj: Let's Blog | D32: 49997 | F32: 3 | G32: 199 | I32: 199 | J32: khyatimehta0@gmail.com | K32: =+919739438900 -> 919739438900 | L32: =CONCAT(J32,K32) -> khyatimehta0@gmail.com919739438900 | M32: INR | N32: FALSE | O32: =VLOOKUP(A32,payment_ids!D:E,2,FALSE) -> upi | P32: captured | Q32: 5/17/2021 9:29 AM | S32: https://community.likeminds.community/ahoj-lets-blog
A33: =VLOOKUP(L33,payment_ids!C:D,2,FALSE) -> pay_HBl9GiClfs6oRm | C33: Ahoj: Let's Blog | D33: 49997 | F33: 3 | G33: 199 | I33: 199 | J33: krishan.bora1990@gmail.com | K33: =+919818529598 -> 919818529598 | L33: =CONCAT(J33,K33) -> krishan.bora1990@gmail.com919818529598 | M33: INR | N33: FALSE | O33: =VLOOKUP(A33,payment_ids!D:E,2,FALSE) -> card | P33: captured | Q33: 5/17/2021 11:54 AM | S33: https://community.likeminds.community/ahoj-lets-blog
A34: =VLOOKUP(L34,payment_ids!C:D,2,FALSE) -> pay_HCDVQQ1ACO1UQ9 | C34: Ahoj: Let's Blog | D34: 49997 | F34: 3 | G34: 199 | I34: 199 | J34: princeparmar6@gmail.com | K34: =+918425046969 -> 918425046969 | L34: =CONCAT(J34,K34) -> princeparmar6@gmail.com918425046969 | M34: INR | N34: FALSE | O34: =VLOOKUP(A34,payment_ids!D:E,2,FALSE) -> upi | P34: captured | Q34: 5/18/2021 3:39 PM | S34: https://community.likeminds.community/ahoj-lets-blog
A35: =VLOOKUP(L35,payment_ids!C:D,2,FALSE) -> pay_HDJzaI79rF6AC3 | C35: Ahoj: Let's Blog | D35: 49997 | F35: 1 | G35: 99 | I35: 99 | J35: muskannagdev342@gmail.com | K35: =+919011926939 -> 919011926939 | L35: =CONCAT(J35,K35) -> muskannagdev342@gmail.com919011926939 | M35: INR | N35: FALSE | O35: =VLOOKUP(A35,payment_ids!D:E,2,FALSE) -> upi | P35: captured | Q35: 5/21/2021 10:39 AM | S35: https://community.likeminds.community/ahoj-lets-blog
A36: =VLOOKUP(L36,payment_ids!C:D,2,FALSE) -> pay_HDLaDN509Luscl | C36: Ahoj: Let's Blog | D36: 49997 | F36: 1 | G36: 99 | I36: 99 | J36: outdoorrebellions@gmail.com | K36: =+919810957676 -> 919810957676 | L36: =CONCAT(J36,K36) -> outdoorrebellions@gmail.com919810957676 | M36: INR | N36: FALSE | O36: =VLOOKUP(A36,payment_ids!D:E,2,FALSE) -> upi | P36: captured | Q36: 5/21/2021 12:12 PM | S36: https://community.likeminds.community/ahoj-lets-blog
A37: =VLOOKUP(L37,payment_ids!C:D,2,FALSE) -> pay_HDLthg6Y2SeBHZ | C37: Ahoj: Let's Blog | D37: 49997 | F37: 3 | G37: 199 | I37: 199 | J37: kanchangusain007@gmail.com | K37: =+919997428605 -> 919997428605 | L37: =CONCAT(J37,K37) -> kanchangusain007@gmail.com919997428605 | M37: INR | N37: FALSE | O37: =VLOOKUP(A37,payment_ids!D:E,2,FALSE) -> upi | P37: captured | Q37: 5/21/2021 6:37 PM | S37: https://community.likeminds.community/ahoj-lets-blog
A38: =VLOOKUP(L38,payment_ids!C:D,2,FALSE) -> pay_HDnBkPwtPD6cWs | C38: Ahoj: Let's Blog | D38: 49997 | F38: 1 | G38: 99 | I38: 99 | J38: ishaan17maxx@gmail.com | K38: =+916393992744 -> 916393992744 | L38: =CONCAT(J38,K38) -> ishaan17maxx@gmail.com916393992744 | M38: INR | N38: FALSE | O38: =VLOOKUP(A38,payment_ids!D:E,2,FALSE) -> upi | P38: captured | Q38: 5/22/2021 3:12 PM | S38: https://community.likeminds.community/ahoj-lets-blog
A39: =VLOOKUP(L39,payment_ids!C:D,2,FALSE) -> pay_HDqS1nWCVitsJy | C39: Ahoj: Let's Blog | D39: 49997 | F39: 1 | G39: 99 | I39: 99 | J39: dua.ankit@gmail.com | K39: =+919810766029 -> 919810766029 | L39: =CONCAT(J39,K39) -> dua.ankit@gmail.com919810766029 | M39: INR | N39: FALSE | O39: =VLOOKUP(A39,payment_ids!D:E,2,FALSE) -> upi | P39: captured | Q39: 5/22/2021 6:24 PM | S39: https://community.likeminds.community/ahoj-lets-blog
A40: =VLOOKUP(L40,payment_ids!C:D,2,FALSE) -> pay_HEXBPcJ144OLNK | C40: Ahoj: Let's Blog | D40: 49997 | F40: 1 | G40: 99 | I40: 99 | J40: raveenakaur544@gmail.com | K40: =+917769846304 -> 917769846304 | L40: =CONCAT(J40,K40) -> raveenakaur544@gmail.com917769846304 | M40: INR | N40: FALSE | O40: =VLOOKUP(A40,payment_ids!D:E,2,FALSE) -> upi | P40: captured | Q40: 5/24/2021 12:12 PM | S40: https://community.likeminds.community/ahoj-lets-blog
...

Sheet payment_ids
A1: email | B1: contact | C1: =CONCAT(A1,B1) -> emailcontact | D1: id
A2: kesavanp_77@yahoo.co.in | B2: =+919841696000 -> 919841696000 | C2: =CONCAT(A2,B2) -> kesavanp_77@yahoo.co.in919841696000 | D2: pay_H5EkwiultUPr2L | E2: card
A3: srishtituteja08@gmail.com | B3: =+919136513535 -> 919136513535 | C3: =CONCAT(A3,B3) -> srishtituteja08@gmail.com919136513535 | D3: pay_H5W1QjuPk82Zxu | E3: upi
A4: yesha.aftab@gmail.com | B4: =+919718917696 -> 919718917696 | C4: =CONCAT(A4,B4) -> yesha.aftab@gmail.com919718917696 | D4: pay_H5aZdWmrCOPv8w | E4: upi
A5: saikishore809@gmail.com | B5: =+919949979809 -> 919949979809 | C5: =CONCAT(A5,B5) -> saikishore809@gmail.com919949979809 | D5: pay_H5ki0PSCLekk4E | E5: upi
A6: kamaliganapathy1998@gmail.com | B6: =+917538888132 -> 917538888132 | C6: =CONCAT(A6,B6) -> kamaliganapathy1998@gmail.com917538888132 | D6: pay_H5qCYp90bYY3IR | E6: upi
A7: himanshusaleria@gmail.com | B7: =+919888470272 -> 919888470272 | C7: =CONCAT(A7,B7) -> himanshusaleria@gmail.com919888470272 | D7: pay_H5seU4HAc7T7Uo | E7: upi
A8: himanshusaleria@gmail.com | B8: =+919888470272 -> 919888470272 | C8: =CONCAT(A8,B8) -> himanshusaleria@gmail.com919888470272 | D8: pay_H5sj9XXNAE8A94 | E8: upi
A9: himanshusaleria@gmail.com | B9: =+919888470272 -> 919888470272 | C9: =CONCAT(A9,B9) -> himanshusaleria@gmail.com919888470272 | D9: pay_H5slgkMTFrOKTg | E9: upi
A10: msnidhi.sharma09@gmail.com | B10: =+919205219728 -> 919205219728 | C10: =CONCAT(A10,B10) -> msnidhi.sharma09@gmail.com919205219728 | D10: pay_H5uhDTPxn4p5GB | E10: upi
A11: 9322296996@tempuser.com | B11: =+919322296996 -> 919322296996 | C11: =CONCAT(A11,B11) -> 9322296996@tempuser.com919322296996 | D11: pay_H5voWwvhqvku3U | E11: card
A12: biswas.manjushree@gmail.com | B12: =+919893352854 -> 919893352854 | C12: =CONCAT(A12,B12) -> biswas.manjushree@gmail.com919893352854 | D12: pay_H6B6gsl5IQqr4D | E12: netbanking
A13: mihirjoshi42@gmail.com | B13: =+917208157797 -> 917208157797 | C13: =CONCAT(A13,B13) -> mihirjoshi42@gmail.com917208157797 | D13: pay_H6BJNaiXBC9lbH | E13: upi
A14: jyotsnab@mdi.ac.in | B14: =+919910448040 -> 919910448040 | C14: =CONCAT(A14,B14) -> jyotsnab@mdi.ac.in919910448040 | D14: pay_H6FI5hqEmx0rQr | E14: upi
A15: saurabhprwl0@gmail.com | B15: =+918860206844 -> 918860206844 | C15: =CONCAT(A15,B15) -> saurabhprwl0@gmail.com918860206844 | D15: pay_H6HCHMdNg2EBjq | E15: wallet
A16: akshita.bpsmv@gmail.com | B16: =+917838168936 -> 917838168936 | C16: =CONCAT(A16,B16) -> akshita.bpsmv@gmail.com917838168936 | D16: pay_H6IQ6rjURebAEN | E16: upi
A17: tara.lanba1999@gmail.com | B17: =+919582439852 -> 919582439852 | C17: =CONCAT(A17,B17) -> tara.lanba1999@gmail.com919582439852 | D17: pay_H6IvfhXVSJtsVU | E17: upi
A18: kushagra249@gmail.com | B18: =+919650225768 -> 919650225768 | C18: =CONCAT(A18,B18) -> kushagra249@gmail.com919650225768 | D18: pay_H6IwUiKNdHcqOa | E18: upi
A19: jai.lanba@likeminds.community | B19: =+919958112731 -> 919958112731 | C19: =CONCAT(A19,B19) -> jai.lanba@likeminds.community919958112731 | D19: pay_H6IynnXpQD3vtu | E19: upi
A20: mukta@mfinserve.co.in | B20: =+919840609903 -> 919840609903 | C20: =CONCAT(A20,B20) -> mukta@mfinserve.co.in919840609903 | D20: pay_H6JewJjwlUQeor | E20: upi
A21: manasgarg28@gmail.com | B21: =+917566220220 -> 917566220220 | C21: =CONCAT(A21,B21) -> manasgarg28@gmail.com917566220220 | D21: pay_H6LyhFlnZPet4L | E21: upi
A22: mahirgupta98@gmail.com | B22: =+919416173796 -> 919416173796 | C22: =CONCAT(A22,B22) -> mahirgupta98@gmail.com919416173796 | D22: pay_H6M18PniZZxhuH | E22: upi
A23: mahirgupta98@gmail.com | B23: =+919416173796 -> 919416173796 | C23: =CONCAT(A23,B23) -> mahirgupta98@gmail.com919416173796 | D23: pay_H6MFOmyP0yzmaG | E23: upi
A24: jaimaran20@gmail.com | B24: =+919344873993 -> 919344873993 | C24: =CONCAT(A24,B24) -> jaimaran20@gmail.com919344873993 | D24: pay_H6MUxD3uiq0qMm | E24: netbanking
A25: nrjmshr14@gmail.com | B25: =+917209943488 -> 917209943488 | C25: =CONCAT(A25,B25) -> nrjmshr14@gmail.com917209943488 | D25: pay_H6OM6mtc3X24p4 | E25: card
A26: tanvimhatre001@gmail.com | B26: =+919969893269 -> 919969893269 | C26: =CONCAT(A26,B26) -> tanvimhatre001@gmail.com919969893269 | D26: pay_H6OZHMGGwhtkMg | E26: card
A27: nandanvangardensolutions@gmail.com | B27: =+917721012926 -> 917721012926 | C27: =CONCAT(A27,B27) -> nandanvangardensolutions@gmail.com917721012926 | D27: pay_H6PH7qQXUHgxfu | E27: upi
A28: nandanvangardensolutions@gmail.com | B28: =+917721012926 -> 917721012926 | C28: =CONCAT(A28,B28) -> nandanvangardensolutions@gmail.com917721012926 | D28: pay_H6PNvHEvhIfTvE | E28: upi
A29: krishnakis@gmail.com | B29: =+919538601160 -> 919538601160 | C29: =CONCAT(A29,B29) -> krishnakis@gmail.com919538601160 | D29: pay_H6Y4xoE46plyib | E29: wallet
A30: abhijit.jha33@gmail.com | B30: =+919711341773 -> 919711341773 | C30: =CONCAT(A30,B30) -> abhijit.jha33@gmail.com919711341773 | D30: pay_H6cZodbxWfXymQ | E30: upi
A31: spoojac@outlook.com | B31: =+919999861974 -> 919999861974 | C31: =CONCAT(A31,B31) -> spoojac@outlook.com919999861974 | D31: pay_H6dDZuXUs5wJYw | E31: upi
A32: dcbs13simranbajaj@gmail.com | B32: =+917389999990 -> 917389999990 | C32: =CONCAT(A32,B32) -> dcbs13simranbajaj@gmail.com917389999990 | D32: pay_H6e19mJSkBnPZl | E32: upi
A33: nawatheygaurav@gmail.com | B33: =+919819252511 -> 919819252511 | C33: =CONCAT(A33,B33) -> nawatheygaurav@gmail.com919819252511 | D33: pay_H6ejsTenhxPtgT | E33: upi
A34: leshanimehra1998@gmail.com | B34: =+918600964699 -> 918600964699 | C34: =CONCAT(A34,B34) -> leshanimehra1998@gmail.com918600964699 | D34: pay_H6gODrRvIOBR2G | E34: upi
A35: jainprachi1385@gmail.com | B35: =+919643061385 -> 919643061385 | C35: =CONCAT(A35,B35) -> jainprachi1385@gmail.com919643061385 | D35: pay_H6gUPHb3HdZe6C | E35: upi
A36: jainprachi1385@gmail.com | B36: =+919643061385 -> 919643061385 | C36: =CONCAT(A36,B36) -> jainprachi1385@gmail.com919643061385 | D36: pay_H6gVGUdkPWXtHP | E36: upi
A37: jainprachi1385@gmail.com | B37: =+919643061385 -> 919643061385 | C37: =CONCAT(A37,B37) -> jainprachi1385@gmail.com919643061385 | D37: pay_H6gWqyN5SdktFR | E37: upi
A38: dezikakol@gmail.com | B38: =+919561542950 -> 919561542950 | C38: =CONCAT(A38,B38) -> dezikakol@gmail.com919561542950 | D38: pay_H6gmIveChQnJtL | E38: netbanking
A39: iamagsusfreak@gmail.com | B39: =+918129282453 -> 918129282453 | C39: =CONCAT(A39,B39) -> iamagsusfreak@gmail.com918129282453 | D39: pay_H6hFPdEWIAM1A2 | E39: upi
A40: kalyanee.bhake@gmail.com | B40: =+919380605339 -> 919380605339 | C40: =CONCAT(A40,B40) -> kalyanee.bhake@gmail.com919380605339 | D40: pay_H6hG9WBnSD7eC3 | E40: upi
...

Sheet Transaction data
A1: payment_id | B1: created_at | C1: Community_id | D1: email | E1: contact | F1: Users | G1: plan_id | H1: Community Name | I1: plan_name | J1: plan_duration | K1: plan_cost | L1: renew | M1: amount | N1: currency | O1: is_international | P1: method | Q1: status | R1: payment_page_url
A2: pay_HMGCDlUtbqpVRR | B2: 6/13/2021 12:46 AM | C2: 49833 | D2: rashmijagtap63@gmail.com | E2: 918983081469 | F2: 17571 | H2: Han Hangul | J2: 1 | K2: 149 | M2: 149 | N2: INR | O2: FALSE | P2: upi | Q2: captured | R2: https://community.likeminds.community/hanhangul
A3: pay_H78Oq2bTVvVg4d | B3: 44321.808 | C3: 49844 | D3: rashmijagtap63@gmail.com | E3: 918983081469 | F3: 17571 | H3: Pharmacology Insiders | J3: 1 | K3: 99 | M3: 99 | N3: INR | O3: FALSE | P3: upi | Q3: captured | R3: https://community.likeminds.community/pharmacology-insiders#Pricing
A4: pay_H79ecxRYLhYp69 | B4: 44321.867 | C4: 50073 | D4: parulmehra84@gmail.com | E4: 919811316353 | F4: 17854 | H4: well being | J4: 1 | K4: 599 | M4: 599 | N4: INR | O4: FALSE | P4: wallet | Q4: captured
A5: pay_HKpsmVMmxwn8wn | B5: 44445.433 | C5: 50073 | D5: parulmehra84@gmail.com | E5: 919811316353 | F5: 17854 | H5: Well Being | J5: 1 | K5: 599 | M5: 599 | N5: INR | O5: FALSE | P5: wallet | Q5: captured | R5: https://hi.likeminds.community/well-being-renewal
A6: pay_H7AoWjPWQKyOjD | B6: 44321.907 | C6: 50073 | D6: sunderr20@gmail.com | E6: 919036755270 | F6: 17904 | H6: well being | J6: 1 | K6: 599 | M6: 599 | N6: INR | O6: FALSE | P6: netbanking | Q6: captured
A7: pay_HIYism5n7QdO6s | B7: 44261.68 | C7: 50073 | D7: sunderr20@gmail.com | E7: 919036755270 | F7: 17904 | H7: Well Being | J7: 1 | K7: 599 | M7: 599 | N7: INR | O7: FALSE | P7: netbanking | Q7: captured | R7: https://hi.likeminds.community/well-being-renewal
A8: pay_H7PltBUerzfnEK | B8: 44352.516 | C8: 50073 | D8: ma.arora@yahoo.in | E8: 919899837660 | F8: 17746 | H8: well being | J8: 1 | K8: 599 | M8: 599 | N8: INR | O8: FALSE | P8: upi | Q8: captured
A9: pay_HKTjWBOEXedT85 | B9: 44414.531 | C9: 50073 | D9: ma.arora@yahoo.in | E9: 919899837660 | F9: 17746 | H9: Well Being | J9: 3 | K9: 1499 | M9: 1499 | N9: INR | O9: FALSE | P9: upi | Q9: captured | R9: https://hi.likeminds.community/well-being-renewal
A10: pay_H7s90KcgRbvZUb | B10: 44382.674 | C10: 49834 | D10: harinsrini@gmail.com | E10: 917708066310 | F10: 17657 | H10: Deutsch In Tandem | J10: 3 | K10: 199 | M10: 199 | N10: INR | O10: FALSE | P10: upi | Q10: captured | R10: https://community.likeminds.community/deutsch-in-tandem
A11: pay_HIURXYtKsQCagS | B11: 44261.505 | C11: 50113 | D11: harinsrini@gmail.com | E11: 917708066310 | F11: 17657 | H11: Learn German with Heer | I11: PLATINUM | J11: 1 | K11: 499 | M11: 499 | N11: INR | O11: FALSE | P11: upi | Q11: captured | R11: https://hi.likeminds.community/d/heer-haria
A12: pay_H7tfEV5loA8BGL | B12: 44382.738 | C12: 50029 | D12: anjalityagi2014@gmail.com | E12: 919868133035 | F12: 17662 | H12: Bonjour Amis French | J12: 1 | K12: 99 | M12: 99 | N12: INR | O12: FALSE | P12: upi | Q12: captured | R12: https://hi.likeminds.community/d/bonjour-amis-french
A13: pay_HOTUXwXvKWQvPi | B13: 6/18/2021 3:05 PM | C13: 50029 | D13: anjalityagi2014@gmail.com | E13: 919868133035 | F13: 17662 | H13: Bonjour Amis French | J13: 3 | K13: 199 | M13: 199 | N13: INR | O13: FALSE | P13: upi | Q13: captured | R13: https://hi.likeminds.community/d/bonjour-amis-french
A14: pay_H7WOZFoeRgG2zC | B14: 44352.786 | C14: 49991 | D14: ajitrai.ajit@gmail.com | E14: 918953547813 | F14: Not Found - Join Record | H14: DeBattlers | J14: 1 | K14: 99 | M14: 99 | N14: INR | O14: FALSE | P14: upi | Q14: captured | R14: https://community.likeminds.community/debattlers
A15: pay_HIqsOugF7OJZZj | B15: 44292.419 | C15: 49991 | D15: ajitrai.ajit@gmail.com | E15: 918953547813 | F15: Not Found - Join Record | H15: DeBattlers | J15: 1 | K15: 99 | M15: 99 | N15: INR | O15: FALSE | P15: upi | Q15: captured | R15: https://community.likeminds.community/debattlers
A16: pay_H7WQcnVXRTRmkm | B16: 44352.787 | C16: 50073 | D16: inv.anshu@gmail.com | E16: 919448847519 | F16: 17738 | H16: well being | J16: 1 | K16: 599 | M16: 599 | N16: INR | O16: FALSE | P16: upi | Q16: captured
A17: pay_HKSQEkxMojypN6 | B17: 44414.477 | C17: 50073 | D17: inv.anshu@gmail.com | E17: 919448847519 | F17: 17738 | H17: Well Being | J17: 1 | K17: 599 | M17: 599 | N17: INR | O17: FALSE | P17: upi | Q17: captured | R17: https://hi.likeminds.community/well-being-renewal
A18: pay_H7WwbyTsx1i8nZ | B18: 44352.81 | C18: 50073 | D18: annusmail@gmail.com | E18: 918447208914 | F18: 17607 | H18: well being | J18: 1 | K18: 599 | M18: 599 | N18: INR | O18: FALSE | P18: netbanking | Q18: captured
A19: pay_HLN4QrIoQo1UVS | B19: 44475.785 | C19: 50073 | D19: annusmail@gmail.com | E19: 918447208914 | F19: 17607 | H19: Well Being | J19: 1 | K19: 599 | M19: 599 | N19: INR | O19: FALSE | P19: netbanking | Q19: captured | R19: https://hi.likeminds.community/well-being-renewal
A20: pay_H8ArZr4fzcp28O | B20: 44413.437 | C20: 49859 | D20: kumar.avinab@yahoo.com | E20: 919632670331 | F20: 17702 | H20: Ladies & Gentlemen | J20: 1 | K20: 99 | M20: 99 | N20: INR | O20: FALSE | P20: wallet | Q20: captured | R20: https://community.likeminds.community/ladies-and-gentlemen
A21: pay_H8Ajs6TmcwP2uq | B21: 44413.438 | C21: 49859 | D21: kumar.avinab@yahoo.com | E21: 919632670331 | F21: 17702 | H21: Ladies & Gentlemen | J21: 1 | K21: 99 | M21: 99 | N21: INR | O21: FALSE | P21: wallet | Q21: captured | R21: https://community.likeminds.community/ladies-and-gentlemen
A22: pay_H8An4U5m9l9dyL | B22: 44413.433 | C22: 50039 | D22: s.swethadri@gmail.com | E22: 919742197987 | F22: 17703 | H22: Happy Ashram | J22: 1 | K22: 99 | M22: 99 | N22: INR | O22: FALSE | P22: upi | Q22: captured | R22: https://hi.likeminds.community/d/happy-ashram
A23: pay_H8hw205XNKRrqg | B23: 44444.784 | C23: 50054 | D23: s.swethadri@gmail.com | E23: 919742197987 | F23: 17703 | H23: Rapto Bhara Jeevan | J23: 1 | K23: 99 | M23: 99 | N23: INR | O23: FALSE | P23: upi | Q23: captured | R23: https://hi.likeminds.community/d/rapto-bhara-jeevan
A24: pay_H8CNawhCwRnUle | B24: 44413.499 | C24: 50073 | D24: rishiti.rao_11@rediffmail.com | E24: 919898956482 | F24: 17761 | H24: well being | J24: 1 | K24: 599 | M24: 599 | N24: INR | O24: FALSE | P24: wallet | Q24: captured
A25: pay_HKpwBUN0Z2PINn | B25: 44445.435 | C25: 50073 | D25: rishiti.rao_11@rediffmail.com | E25: 919898956482 | F25: 17761 | H25: Well Being | J25: 1 | K25: 599 | M25: 599 | N25: INR | O25: FALSE | P25: wallet | Q25: captured | R25: https://hi.likeminds.community/well-being-renewal
A26: pay_H8DtE8iMVlbKl1 | B26: 44413.559 | C26: 50044 | D26: gladiators.eternity@gmail.com | E26: 918886237899 | F26: 17710 | H26: Through Thick and Thin | J26: 1 | K26: 349 | M26: 349 | N26: INR | O26: FALSE | P26: upi | Q26: captured | R26: https://hi.likeminds.community/d/through-thick-and-thin
A27: pay_HJKVdqR9dkfIo6 | B27: 44322.627 | C27: 50044 | D27: gladiators.eternity@gmail.com | E27: 918886237899 | F27: 17710 | H27: Through Thick and Thin | J27: 3 | K27: 599 | M27: 599 | N27: INR | O27: FALSE | P27: upi | Q27: captured | R27: https://hi.likeminds.community/d/through-thick-and-thin
A28: pay_H8FRhmUKx85pZI | B28: 44413.623 | C28: 50031 | D28: guptamona911@gmail.com | E28: 919322798720 | F28: 0 | H28: Khushi Se Yoga | J28: 1 | K28: 99 | M28: 99 | N28: INR | O28: FALSE | P28: card | Q28: captured | R28: https://hi.likeminds.community/khushi-se-yoga
A29: pay_H8kKtxYR8s3iPY | B29: 44444.882 | C29: 49994 | D29: guptamona911@gmail.com | E29: 919322798720 | F29: 0 | H29: Yo Geek | J29: 3 | K29: 199 | M29: 199 | N29: INR | O29: FALSE | P29: card | Q29: captured | R29: https://community.likeminds.community/yo-geek-the-modern-yogi
A30: pay_H8gpu2z42QNfro | B30: 44444.739 | C30: 50043 | D30: sanket.kondekar4@gmail.com | E30: 917972793242 | F30: 17824 | H30: Transformed Finance Professionals | J30: 1 | K30: 99 | M30: 99 | N30: INR | O30: FALSE | P30: upi | Q30: captured | R30: https://hi.likeminds.community/d/transformed-finance-professionals
A31: pay_HLdrCmweG25Sp0 | B31: 44506.47 | C31: 50043 | D31: sanket.kondekar4@gmail.com | E31: 917972793242 | F31: 17824 | H31: Transformed Finance Professionals | J31: 3 | K31: 199 | M31: 199 | N31: INR | O31: FALSE | P31: upi | Q31: captured | R31: https://hi.likeminds.community/d/transformed-finance-professionals
A32: pay_H8h7Z0hESE86Nv | B32: 44444.751 | C32: 49998 | D32: kratirajak971@gmail.com | E32: 919713435860 | F32: 17825 | H32: The Smart Work for NEET- UG | J32: 1 | K32: 99 | M32: 99 | N32: INR | O32: FALSE | P32: upi | Q32: captured | R32: https://community.likeminds.community/the-smart-work-for-neet-ug
A33: pay_HIsbIwZrdQlRES | B33: 44292.49 | C33: 49998 | D33: kratirajak971@gmail.com | E33: 919713435860 | F33: 17825 | H33: The Smart Work for NEET- UG | J33: 3 | K33: 199 | M33: 199 | N33: INR | O33: FALSE | P33: upi | Q33: captured | R33: https://community.likeminds.community/the-smart-work-for-neet-ug
A34: pay_H8iUznqpQgG5Ys | B34: 44444.807 | C34: 50054 | D34: gaurav.sindhiya@gmail.com | E34: 919993209318 | F34: 17834 | H34: Rapto Bhara Jeevan | J34: 1 | K34: 99 | M34: 99 | N34: INR | O34: FALSE | P34: wallet | Q34: captured | R34: https://hi.likeminds.community/d/rapto-bhara-jeevan
A35: pay_HIpQuvSIW1JbZi | B35: 44292.36 | C35: 50054 | D35: gaurav.sindhiya@gmail.com | E35: 919993209318 | F35: 17834 | H35: Rapto Bhara Jeevan | J35: 1 | K35: 99 | M35: 99 | N35: INR | O35: FALSE | P35: wallet | Q35: captured | R35: https://hi.likeminds.community/d/rapto-bhara-jeevan
A36: pay_H8jici6xtW4qW9 | B36: 44444.857 | C36: 50009 | D36: lakshmimadeti23@gmail.com | E36: 919912636113 | F36: Not Found - Join Record | H36: Blooming Rush | J36: 1 | K36: 99 | M36: 99 | N36: INR | O36: FALSE | P36: upi | Q36: captured | R36: https://hi.likeminds.community/blooming-rush
A37: pay_HHBqVsd4JPCpJn | B37: 5/31/2021 5:16 AM | C37: 50076 | D37: lakshmimadeti23@gmail.com | E37: 919912636113 | F37: 17838 | H37: Spokken | J37: 1 | K37: 199 | M37: 199 | N37: INR | O37: FALSE | P37: upi | Q37: captured | R37: https://hi.likeminds.community/d/spokken-2
A38: pay_H8JuvMG5c9y8og | B38: 44413.806 | C38: 50073 | D38: bharathipaddy@gmail.com | E38: 919844939825 | F38: 17751 | H38: well being | J38: 1 | K38: 599 | M38: 599 | N38: INR | O38: FALSE | P38: wallet | Q38: captured
A39: pay_HKU93mJD7JoOEL | B39: 44414.547 | C39: 50073 | D39: bharathipaddy@gmail.com | E39: 919844939825 | F39: 17751 | H39: Well Being | J39: 1 | K39: 599 | M39: 599 | N39: INR | O39: FALSE | P39: wallet | Q39: captured | R39: https://hi.likeminds.community/well-being-renewal
A40: pay_HDqTwJrJrBqUj1 | B40: 5/22/2021 6:25 PM | C40: 50079 | D40: sanya.sabharwal@gmail.com | E40: 919953295925 | F40: 17839 | H40: Happiness Fountain | J40: 1 | K40: 199 | M40: 199 | N40: INR | O40: FALSE | P40: upi | Q40: captured | R40: https://hi.likeminds.community/d/happiness-fountain
...

Sheet Live Plan Data
A1: Community Name | B1: Community_id | C1: Plan_exists | D1: Amount - strike | E1: Amount | F1: Description | G1: Link | H1: Dump | I1: Plan_id | J1: Status
A2: A Blue Lotus Life | B2: 50143 | C2: TRUE | D2: 499 | E2: 199 | F2: <ul><li>Learn the art of long and short conversations at work</li><li>How do values shape behavior</li><li>Free participation with team in 1 OMGrr! event</li><li>1 Free ticket to attend 1 Cuddles &amp; Curveballs</li><li>Be Blue Bud: Practise Session for interviews &amp; presentation</li></ul><p><a href="https://rzp.io/l/DeutschInTandem" target="_blank"><br></a></p> | G2: https://payment.likeminds.community/?plan_id=13c0b553-5d91-4d31-b4bc-88d880628869 | H2: =IFERROR(__xludf.DUMMYFUNCTION("SPLIT(G2,""="")"),"https://payment.likeminds.community/?plan_id") -> https://payment.likeminds.community/?plan_id | I2: =IFERROR(__xludf.DUMMYFUNCTION("""COMPUTED_VALUE"""),"13c0b553-5d91-4d31-b4bc-88d880628869") -> 13c0b553-5d91-4d31-b4bc-88d880628869 | J2: Active
A3: A Blue Lotus Life | B3: 50143 | C3: TRUE | D3: 799 | E3: 399 | F3: <ul><li>Learn the art of long and short conversations at work</li><li>How do values shape behavior</li><li>Be Blue Blossom: Practise Session for interviews, public speaking, speech writing, presentation</li><li>Reasons for writing at work </li><li>'2F's that makes your writing thoughtful</li><li>Free participation with team in 2 OMGrr! events</li><li>2 Free ticket to attend 2 Cuddles &amp; Curveballs</li><li>Attend Workshops with an external speaker</li></ul><p><a href="https://rzp.io/l/DeutschInTandem" target="_blank"><br></a></p> | G3: https://payment.likeminds.community/?plan_id=f769f468-4a1f-47bd-a73b-f158d7cd9797 | H3: =IFERROR(__xludf.DUMMYFUNCTION("SPLIT(G3,""="")"),"https://payment.likeminds.community/?plan_id") -> https://payment.likeminds.community/?plan_id | I3: =IFERROR(__xludf.DUMMYFUNCTION("""COMPUTED_VALUE"""),"f769f468-4a1f-47bd-a73b-f158d7cd9797") -> f769f468-4a1f-47bd-a73b-f158d7cd9797 | J3: Active
A4: A Blue Lotus Life | B4: 50143 | C4: TRUE | D4: 1499 | E4: 999 | F4: <ul><li>Learn the art of long and short conversations at work.</li><li>Understand the importance of body language and being receptive</li><li>Reasons for writing at work. </li><li>'2F's that makes your writing thoughtful.</li><li>Master the art of being a good listener and speaker</li><li>Learn to paraphrase &amp; how to use it impactfully</li><li>Attend Workshops with an external speaker</li><li>Get access to one on one practice sessions for interviews, public speaking, speech writing, presentation.</li><li>Free participation with team in 3 OMGrr! events + 1 Family exclusive OMGrr!</li><li>3 Free ticket to attend 3 Cuddles &amp; Curveballs</li><li>1 session of Live A Blue Lotus Life which includes a one on one consultation.</li></ul><p><a href="https://rzp.io/l/DeutschInTandem" target="_blank"><br></a></p> | G4: https://payment.likeminds.community/?plan_id=5f18b70b-7596-4800-968b-3425c2266e5e | H4: =IFERROR(__xludf.DUMMYFUNCTION("SPLIT(G4,""="")"),"https://payment.likeminds.community/?plan_id") -> https://payment.likeminds.community/?plan_id | I4: =IFERROR(__xludf.DUMMYFUNCTION("""COMPUTED_VALUE"""),"5f18b70b-7596-4800-968b-3425c2266e5e") -> 5f18b70b-7596-4800-968b-3425c2266e5e | J4: Active
A5: A Meeting with Self | B5: 50146 | C5: TRUE | D5: 299 | E5: 99 | F5: <ul><li>Learn simple mindfulness techniques to breakthrough your mind &amp; its patterns</li><li>Identify your authentic self</li><li>Improve the quality of your life through regular mediation practice</li><li>Get access to Full moon Meditation session<a href="https://rzp.io/l/DeutschInTandem" target="_blank"><br></a></li></ul> | G5: https://payment.likeminds.community/?plan_id=c569cb32-9e1e-4231-a60f-b7dd838e051c | H5: =IFERROR(__xludf.DUMMYFUNCTION("SPLIT(G5,""="")"),"https://payment.likeminds.community/?plan_id") -> https://payment.likeminds.community/?plan_id | I5: =IFERROR(__xludf.DUMMYFUNCTION("""COMPUTED_VALUE"""),"c569cb32-9e1e-4231-a60f-b7dd838e051c") -> c569cb32-9e1e-4231-a60f-b7dd838e051c | J5: Active
A6: A Meeting with Self | B6: 50146 | C6: TRUE | D6: 499 | E6: 199 | F6: <ul><li>Learn simple mindfulness techniques to breakthrough your min &amp; its patterns</li><li>Identify your authentic self</li><li>Improve the quality of your life through regular mediation practice</li><li>Get access to Full moon Meditation session<a href="https://rzp.io/l/DeutschInTandem" target="_blank"><br></a></li></ul> | G6: https://payment.likeminds.community/?plan_id=507beaf4-02a0-4413-abe9-bfe08e9cd3f2 | H6: =IFERROR(__xludf.DUMMYFUNCTION("SPLIT(G6,""="")"),"https://payment.likeminds.community/?plan_id") -> https://payment.likeminds.community/?plan_id | I6: =IFERROR(__xludf.DUMMYFUNCTION("""COMPUTED_VALUE"""),"507beaf4-02a0-4413-abe9-bfe08e9cd3f2") -> 507beaf4-02a0-4413-abe9-bfe08e9cd3f2 | J6: Active
A7: A Meeting with Self | B7: 50146 | C7: TRUE | D7: 799 | E7: 349 | F7: <ul><li>Learn simple mindfulness techniques to breakthrough your mind &amp; its patterns</li><li>Identify your authentic self</li><li>Improve the quality of your life through regular mediation practice</li><li>Get access to Full moon Meditation session<a href="https://rzp.io/l/DeutschInTandem" target="_blank"><br></a></li></ul> | G7: https://payment.likeminds.community/?plan_id=aee90a54-bbfd-4a14-bca2-5f8528e05d07 | H7: =IFERROR(__xludf.DUMMYFUNCTION("SPLIT(G7,""="")"),"https://payment.likeminds.community/?plan_id") -> https://payment.likeminds.community/?plan_id | I7: =IFERROR(__xludf.DUMMYFUNCTION("""COMPUTED_VALUE"""),"aee90a54-bbfd-4a14-bca2-5f8528e05d07") -> aee90a54-bbfd-4a14-bca2-5f8528e05d07 | J7: Active
A8: Azhar's Speaking Club | B8: 50123 | C8: TRUE | D8: 499 | E8: 299 | F8: <p>(Focus – Communication, Basic to Upper-Intermediate Level)</p><ul><li>Attend 4 Live Webinars from any of the topics on English grammar, vocabulary, writing skills, Interview skills, Pronunciation, and Interpersonal skills</li><li>Participate in every week’s Community’s Challenges and improve your communication skills</li><li>Get 30 Minutes recorded on-demand videos on Effective Communication Skills – 2 Videos per week</li><li>Receive PDF English grammar, vocabulary and, writing drills to upskill your English proficiency skills (2 Worksheets per week)</li><li>Receive Bite-size video tips on Vocabulary, Grammar, and Pronunciation</li><li>Participate in Community Roleplays activities and develop persuasive speaking skills</li><li>Participate in Live / Chat Discussions and get tips from the experts<br></li></ul> | G8: https://payment.likeminds.community/?plan_id=f6c6a3a4-b29d-429e-96b6-e3c01572dfd7 | H8: =IFERROR(__xludf.DUMMYFUNCTION("SPLIT(G8,""="")"),"https://payment.likeminds.community/?plan_id") -> https://payment.likeminds.community/?plan_id | I8: =IFERROR(__xludf.DUMMYFUNCTION("""COMPUTED_VALUE"""),"f6c6a3a4-b29d-429e-96b6-e3c01572dfd7") -> f6c6a3a4-b29d-429e-96b6-e3c01572dfd7 | J8: Active
A9: Azhar's Speaking Club | B9: 50123 | C9: TRUE | D9: 1199 | E9: 499 | F9: <p>(Focus – Business Communication, Pre-Intermediate to Advanced Level)</p><ul><li>Attend 4 Live Webinars from any of the topics on Business grammar and vocabulary, Business writing, Meeting skills, Presentation, and Corporate Culture skills</li><li>Participate in Every week’s Community’s Challenges and improve your workplace communication skills</li><li>Get 30 Minutes recorded on-demand videos on Effective Communication Skills – 2 Videos per week</li><li>Receive PDF Business English grammar and vocabulary worksheets and improve your Business English Communication skills – 2 Worksheets per week</li><li>Receive Bite-size video tips on Vocabulary, Grammar, and Pronunciation</li><li>Participate in Community Roleplays activities and develop persuasive speaking skills</li><li>Participate in Live / Chat Discussions and get tips from the experts<br></li></ul> | G9: https://payment.likeminds.community/?plan_id=51e33f1a-4b78-4ca5-b009-6e460fbde9fa | H9: =IFERROR(__xludf.DUMMYFUNCTION("SPLIT(G9,""="")"),"https://payment.likeminds.community/?plan_id") -> https://payment.likeminds.community/?plan_id | I9: =IFERROR(__xludf.DUMMYFUNCTION("""COMPUTED_VALUE"""),"51e33f1a-4b78-4ca5-b009-6e460fbde9fa") -> 51e33f1a-4b78-4ca5-b009-6e460fbde9fa | J9: Active
A10: Azhar's Speaking Club | B10: 50123 | C10: TRUE | D10: 3999 | E10: 1999 | F10: <p>(Focus – Personalized Communication Goals)</p><ul><li>‘Speak Up’ Subscription FREE</li><li>‘Professional’ Subscription FREE</li><li>Get 4 Personalized One to One Private Lessons with Expert Trainer Dr. Azhar Ahmed. 30 Mins each session on General / Business Communication topics as per your choice. (Each session - 400, total worth ₹.1600)</li><li>Collaborate with Dr. Azhar and become a co-host/host for conducting his live webinars on Effective Communication Skills</li><li>Involve in Personalized speaking/writing challenges and receive individualized audio/written feedback and remedial. (4 Challenges/week)</li><li>Receive Personalized worksheet drills and overcome your communication flaws. <br></li></ul><p>‍</p><p>‍</p> | G10: https://payment.likeminds.community/?plan_id=035f8c9a-0438-4476-91eb-314a8b92181f | H10: =IFERROR(__xludf.DUMMYFUNCTION("SPLIT(G10,""="")"),"https://payment.likeminds.community/?plan_id") -> https://payment.likeminds.community/?plan_id | I10: =IFERROR(__xludf.DUMMYFUNCTION("""COMPUTED_VALUE"""),"035f8c9a-0438-4476-91eb-314a8b92181f") -> 035f8c9a-0438-4476-91eb-314a8b92181f | J10: Active
A11: BAKERPRENEURSHIP | B11: 50137 | C11: TRUE | D11: 299 | E11: 99 | F11: <ul><li>Interactive Sessions</li><li>Workshops to help you up your baking game</li><li>Enhance your Baking skills with our live training sessions</li><li>one-on-one consultations with community expert</li><li>Access to premium community of bakers<a href="https://rzp.io/l/DeutschInTandem" target="_blank">‍</a></li></ul><p><a href="https://rzp.io/l/DeutschInTandem" target="_blank">‍<br></a></p> | G11: https://payment.likeminds.community/?plan_id=56a4c42d-5825-40a2-822c-085d0bf62600 | H11: =IFERROR(__xludf.DUMMYFUNCTION("SPLIT(G11,""="")"),"https://payment.likeminds.community/?plan_id") -> https://payment.likeminds.community/?plan_id | I11: =IFERROR(__xludf.DUMMYFUNCTION("""COMPUTED_VALUE"""),"56a4c42d-5825-40a2-822c-085d0bf62600") -> 56a4c42d-5825-40a2-822c-085d0bf62600 | J11: Active
A12: BAKERPRENEURSHIP | B12: 50137 | C12: TRUE | D12: 499 | E12: 199 | F12: <ul><li>Interactive Sessions</li><li>Workshops to help you up your baking game</li><li>Enhance your Baking skills with our live training sessions</li><li>one-on-one consultations with community expert</li><li>Access to premium community of bakers</li><li>Monetization and collaborations<a href="https://rzp.io/l/DeutschInTandem" target="_blank"><br></a></li></ul> | G12: https://payment.likeminds.community/?plan_id=b3357429-e535-4d80-a3b8-248cd2cd4f9f | H12: =IFERROR(__xludf.DUMMYFUNCTION("SPLIT(G12,""="")"),"https://payment.likeminds.community/?plan_id") -> https://payment.likeminds.community/?plan_id | I12: =IFERROR(__xludf.DUMMYFUNCTION("""COMPUTED_VALUE"""),"b3357429-e535-4d80-a3b8-248cd2cd4f9f") -> b3357429-e535-4d80-a3b8-248cd2cd4f9f | J12: Active
A13: BAKERPRENEURSHIP | B13: 50137 | C13: TRUE | D13: 799 | E13: 349 | F13: <ul><li>Interactive Sessions</li><li>Workshops to help you up your baking game</li><li>Enhance your Baking skills with our live training sessions</li><li>one-on-one consultations with community expert</li><li>Access to premium community of bakers</li><li>Monetization and collaborations<a href="https://rzp.io/l/DeutschInTandem" target="_blank"><br></a></li></ul> | G13: https://payment.likeminds.community/?plan_id=7d5492e5-4806-4570-9fb4-d67785bb73f3 | H13: =IFERROR(__xludf.DUMMYFUNCTION("SPLIT(G13,""="")"),"https://payment.likeminds.community/?plan_id") -> https://payment.likeminds.community/?plan_id | I13: =IFERROR(__xludf.DUMMYFUNCTION("""COMPUTED_VALUE"""),"7d5492e5-4806-4570-9fb4-d67785bb73f3") -> 7d5492e5-4806-4570-9fb4-d67785bb73f3 | J13: Active
A14: Being Earthable | B14: 50065 | C14: TRUE | D14: 799 | E14: 349 | F14: <ul><li>Be a part of workshops/webinars from experts in low-waste living</li><li>Interactive sessions</li><li>Product Recommendations</li><li>Attend Community webinars to learn the DIY products that are sustainable.</li><li>One-One Consultation once a month</li></ul> | G14: https://payment.likeminds.community/?plan_id=913ed34f-a4bf-4efd-83eb-d64f7c21201c | H14: =IFERROR(__xludf.DUMMYFUNCTION("SPLIT(G14,""="")"),"https://payment.likeminds.community/?plan_id") -> https://payment.likeminds.community/?plan_id | I14: =IFERROR(__xludf.DUMMYFUNCTION("""COMPUTED_VALUE"""),"913ed34f-a4bf-4efd-83eb-d64f7c21201c") -> 913ed34f-a4bf-4efd-83eb-d64f7c21201c | J14: Active
